tests/complex_23.in
40
o
38 S 100 AMP 293 50
4 B 101 BBAR 1398 136
9 S 102 A 762 330
27 S 103 ASC 402 837
1 B 104 AGTI 1470 340
30 B 105 AMP 507 687
24 S 106 AMCR 1410 752
4 B 107 ALE 460 435
7 B 108 AGAC 997 975
28 S 109 ATEK 1122 611
37 B 110 ACP^A 649 150
28 S 111 BFAM 1743 393
33 B 112 BEPC 951 570
31 S 113 ASIX 1157 459
13 S 114 BJ 935 200
11 S 115 ATH^D 1428 507
20 S 116 AQNB 1750 153
16 B 117 BIG 279 129
21 B 118 BME 509 944
13 S 119 BML^G 460 866
37 B 120 AVNS 882 487
35 S 121 ALB 1232 462
35 B 122 ACHR 626 743
4 B 123 BIG 1744 799
19 B 124 AHT^G 1807 361
6 S 125 BKN 671 502
34 B 126 AMX 1296 553
34 B 127 BFS^E 1255 699
35 S 128 BFS^E 754 454
14 S 129 ABB 1500 881
10 B 130 ACA 1392 58
0 B 131 ACR^D 1123 978
9 B 132 ALG 142 976
26 S 133 ABT 335 776
5 B 134 BKE 808 421
20 S 135 AMPY 123 611
9 B 136 AGRO 1059 954
36 S 137 ASB^E 1528 992
18 B 138 BGX 974 131
34 S 139 BJ 1838 239
7 S 140 ALTG^A 989 555
0 B 141 BKKT 1064 900
35 B 142 AUB 1120 275
12 B 143 APO 1914 313
33 B 144 BAC^P 1022 529
27 S 145 BBN 742 692
1 S 146 AJXA 1135 228
28 B 147 AVYA 431 411
36 B 148 ALV 199 696
37 B 149 BEPC 506 786
24 B 150 ATH^B 1683 328
20 B 151 AQNU 1675 480
19 B 152 ATH^D 400 956
24 B 153 AAP 1237 482
15 B 154 AHL^E 1916 648
9 S 155 BGX 370 628
31 S 156 AGM^G 1283 170
0 S 157 APH 1462 417
11 S 158 AENZ 539 64
28 S 159 AHH^A 1575 991
34 S 160 ALV 457 128
9 B 161 ARIS 1885 684
13 S 162 AUB 140 695
9 B 163 BAM 478 133
29 B 164 AR 1713 525
6 B 165 ATHM 933 111
39 S 166 AAIN 1213 820
13 S 167 B 1677 771
28 B 168 ABT 990 295
30 B 169 AGM^D 1341 592
31 B 170 ARR^C 1794 422
24 S 171 ARC 1190 940
10 B 172 AGM^D 1893 431
33 B 173 AUY 127 401
17 B 174 BBN 288 536
19 B 175 APO 666 872
36 S 176 AXR 1147 211
35 B 177 BIPI 1864 141
4 S 178 BE 192 757
20 S 179 BFAM 1501 86
37 B 180 ATR 1919 815
30 B 181 ATEK 296 498
30 B 182 BGSF 932 554
33 B 183 ARIS 796 827
17 S 184 ABR^D 1548 283
8 B 185 AGTI 608 538
37 B 186 BBU 1048 85
5 B 187 AGO 1282 353
36 B 188 BAH 338 755
27 B 189 AHL^E 172 359
21 B 190 BKKT 279 219
17 B 191 ARGD 1752 597
31 B 192 AR 461 235
23 B 193 AGR 1011 121
35 S 194 BAC^P 1677 614
24 S 195 AIRC 1513 897
30 B 196 BAC^S 1137 196
8 S 197 BBUC 891 577
6 S 198 APD 657 360
27 B 199 BHLB 1989 385
30 B 200 ARL 337 75
26 B 201 ATIP 1235 450
38 B 202 ASPN 1662 702
20 S 203 APD 422 220
28 B 204 AZUL 1937 814
18 S 205 BFS^E 476 210
17 S 206 AL^A 613 757
37 S 207 AJX 369 442
35 B 208 AUD 308 170
13 B 209 AMG 1109 468
37 B 210 AIV 940 187
13 S 211 BIP^B 1060 261
22 S 212 BCO 1922 351
30 S 213 AZO 569 536
34 B 214 AJG 1481 884
32 S 215 ATIP 1461 216
13 B 216 ATTO 1646 280
39 S 217 BAC^B 1699 963
36 S 218 BME 1344 57
39 S 219 AHT^D 1013 333
33 B 220 AMH^H 1310 194
20 S 221 AP 1845 555
21 B 222 AVA 704 10
20 B 223 AGS 1443 398
34 S 224 APTV^A 585 637
30 S 225 AGS 342 370
11 S 226 AGO 943 595
28 S 227 AJX 551 897
39 S 228 AAIC^B 1849 409
8 B 229 APTV 1970 612
16 S 230 AJRD 1855 29
0 S 231 AMX 186 827
5 B 232 AVA 423 345
24 S 233 APE 752 658
28 B 234 BALL 1547 65
30 S 235 ACRE 1047 667
17 B 236 BKE 664 202
2 S 237 AIRC 254 496
26 S 238 ALC 742 820
26 B 239 AHT^H 1136 421
11 S 240 BIO 1568 196
12 S 241 ALCC 1984 824
13 B 242 ACR^C 1545 563
14 S 243 BFH 411 936
14 S 244 BLND 835 525
29 B 245 AZZ 1474 392
27 S 246 ASB^E 1633 478
35 S 247 AAIC^B 543 827
35 S 248 AFL 506 715
15 S 249 BGR 862 1000
20 B 250 BEPH 353 24
14 S 251 AVAL 1284 975
19 B 252 ACR 720 977
4 S 253 BEDU 334 730
23 S 254 BF/A 569 417
13 S 255 AXAC 237 865
1 S 256 AFB 1321 667
13 S 257 BLW 206 184
14 S 258 BLCO 1741 387
39 B 259 AGS 1916 52
26 S 260 BEPI 205 120
3 B 261 BAX 1363 742
29 B 262 ACP^A 611 856
1 B 263 AFGE 1619 166
14 B 264 AWK 210 470
5 S 265 BHK 286 478
22 B 266 BAH 1296 402
17 S 267 AAIC^C 1483 516
25 S 268 AVNT 945 992
33 B 269 AKO/B 1314 517
27 S 270 AEL^B 1979 427
17 B 271 BCAT 307 597
21 B 272 AEO 733 628
24 B 273 ADC^A 514 535
29 B 274 BIG 1933 316
6 B 275 AEFC 1322 591
5 B 276 ABR 1179 624
32 B 277 BLND 476 881
13 B 278 AEL^B 922 605
18 B 279 BHR^D 1654 421
8 B 280 BFZ 418 854
22 S 281 ARCH 780 533
0 B 282 ATH^B 874 422
31 B 283 AVNT 991 311
2 B 284 AROC 1346 948
19 B 285 AAC 1036 811
4 B 286 BGSF 1175 368
26 B 287 ARL 311 135
3 S 288 ATH^A 677 636
37 B 289 ATTO 1644 129
2 S 290 BERY 507 177
4 S 291 ADT 650 635
11 S 292 ATH^E 1000 394
27 S 293 AENZ 1169 201
31 B 294 AFGE 373 971
28 S 295 AGX 1352 861
21 S 296 BHK 814 183
36 B 297 ASPN 176 724
32 B 298 BCX 1001 940
24 S 299 AHT^F 1170 18
5 S 300 AMPY 241 576
13 B 301 AGX 1633 399
27 B 302 BHV 1430 843
38 B 303 AVYA 1775 1000
33 S 304 ATAQ 322 60
31 B 305 BBDC 1313 60
16 S 306 BAC^B 1914 911
37 S 307 ARL 756 652
38 S 308 BKSY 397 364
34 S 309 BML^H 1145 716
36 B 310 ABG 926 109
28 S 311 BEPC 1838 310
24 B 312 AMPS 428 877
30 S 313 AVA 1756 211
1 S 314 ALLE 1120 29
5 S 315 AVTR 1868 346
22 B 316 AMH^G 1437 840
36 B 317 BMA 120 731
20 B 318 BF/B 1770 52
9 S 319 BLX 525 726
29 B 320 ATO 155 930
6 B 321 ARC 1008 110
37 B 322 ARMK 206 101
16 S 323 BDJ 1481 386
3 S 324 AU 1134 855
5 S 325 AI 413 34
28 B 326 BFH 1913 965
25 S 327 BHK 1890 827
35 S 328 BHC 775 175
1 S 329 AIRC 1399 88
34 B 330 ARGD 550 422
22 B 331 ACR^D 348 882
33 S 332 ABR^F 1523 218
14 S 333 BAH 1449 275
28 S 334 ALG 345 360
10 B 335 BFK 1771 479
8 S 336 AHT 240 987
15 B 337 BFAC 537 342
21 S 338 BHV 185 780
21 B 339 BKH 841 369
6 S 340 BIGZ 413 700
17 S 341 ARGO^A 537 155
21 S 342 BAC^M 1187 298
36 B 343 BJ 1463 759
8 S 344 AUY 1512 267
27 S 345 AL^A 822 299
11 S 346 AIT 1750 374
39 B 347 AQNA 200 693
8 S 348 BG 338 950
8 B 349 BEST 731 845
32 S 350 AGD 1390 705
4 S 351 BCAT 1459 232
30 S 352 ACV 662 598
35 S 353 AMC 944 135
38 S 354 BBUC 373 317
35 S 355 AGRO 632 746
11 B 356 APTV 832 623
7 B 357 ACR^C 1986 766
0 B 358 AES 261 718
23 S 359 AMT 279 717
13 S 360 BFAC 479 502
15 S 361 AUD 512 496
25 S 362 ARW 356 226
8 S 363 BDJ 370 776
20 S 364 ATH^E 869 40
12 S 365 BBN 1494 973
39 S 366 ALLG 1552 221
4 S 367 ARDC 259 828
16 S 368 ALLE 1417 429
29 S 369 AORT 1232 694
38 S 370 BERY 1897 114
36 S 371 BAC^O 1157 336
9 B 372 ASGN 128 683
23 S 373 BHR^D 741 689
6 B 374 ARMK 270 631
24 S 375 ADX 922 369
27 B 376 AEO 1699 883
29 B 377 AMT 303 14
19 B 378 ARLO 876 470
31 B 379 BGH 1358 317
39 S 380 ACCO 160 54
14 S 381 AGM 1606 843
28 S 382 AMRC 1790 26
29 S 383 AVAL 643 310
23 S 384 ASAI 1688 511
21 S 385 BHLB 1033 605
7 B 386 ACV 1009 780
17 B 387 AUY 1360 183
13 S 388 ALG 1759 730
6 B 389 ACCO 1033 755
18 B 390 AGI 767 174
1 S 391 ALSN 614 652
17 S 392 ACR^C 369 816
9 B 393 AFB 1336 554
3 S 394 BAH 1820 38
30 S 395 BDN 1510 184
20 S 396 AWP 517 748
24 S 397 APGB 386 561
20 S 398 AGM^E 1170 645
13 B 399 AIG 1942 88
14 S 400 ALSN 1972 928
19 B 401 AFG 1096 297
8 B 402 BIO/B 651 839
12 S 403 ACRE 1388 403
19 B 404 BFS 1641 24
31 S 405 AQN 328 668
25 S 406 ACHR 772 958
4 B 407 ADT 1473 253
16 B 408 AC 1901 675
26 S 409 BFH 646 424
8 S 410 BMAC 872 828
35 B 411 BE 581 253
9 S 412 ARW 593 323
15 B 413 AFGC 1158 756
5 B 414 AGM^C 900 341
29 S 415 ASX 1516 193
33 S 416 BFS 1995 379
12 B 417 ASPN 1117 815
23 B 418 AMBC 425 590
11 S 419 ANVS 1468 42
37 S 420 BCO 1917 453
1 S 421 ALG 1910 669
20 B 422 BBD 110 362
35 S 423 ABR^E 209 438
19 S 424 ACRE 1140 134
27 B 425 AUB^A 380 406
24 B 426 ARW 436 245
22 B 427 ARIS 1822 740
5 S 428 AN 155 632
18 B 429 BEN 476 435
38 B 430 AXL 164 418
15 S 431 BGH 1676 410
12 S 432 BBD 155 892
12 B 433 BCX 1289 798
28 S 434 AHT^D 299 263
10 S 435 BMA 371 81
23 S 436 AGX 184 689
35 B 437 BEDU 1400 663
12 S 438 AMTD 1139 164
25 S 439 ATH^A 1142 178
23 B 440 ABR^D 1878 905
9 S 441 AGR 1900 792
29 S 442 AJX 416 667
13 S 443 ALC 784 662
18 B 444 BLD 973 738
5 S 445 BIPC 965 61
19 S 446 BBU 969 437
17 B 447 BHIL 258 25
0 S 448 APG 1622 992
35 B 449 AZUL 1314 987
4 S 450 BGX 283 900
36 S 451 ASX 1583 349
0 S 452 BG 1359 260
18 B 453 AGS 1944 283
4 B 454 A 1797 894
5 S 455 AER 1915 178
13 B 456 BIGZ 240 307
1 B 457 BK 732 303
9 B 458 BLE 127 516
13 S 459 BIO 1681 511
32 B 460 BC^C 1562 884
14 B 461 ASB^F 1014 516
21 B 462 BHVN 1852 834
26 S 463 AUY 530 686
39 B 464 AMK 1798 552
15 S 465 AGM^C 1834 97
