tests/complex_24.in
40
o
22 B 101 AWR 1765 469
30 B 102 AM 575 888
7 S 103 B 381 723
22 S 104 A 1813 119
9 B 105 BKDT 1159 566
34 B 106 AVNT 1640 431
18 B 107 AKO/A 898 408
4 B 108 BGSX 571 75
21 C 152
9 S 110 ALE 100 273
12 C 1056
11 B 112 AOS 1568 92
7 S 113 AHT^G 1846 752
11 C 840
6 C 483
26 S 116 AWK 1493 222
5 S 117 APH 592 127
5 S 118 AVY 1931 17
3 C 856
6 B 120 ATH^A 1060 195
22 B 121 ASAN 140 543
15 S 122 AGR 1176 815
26 C 1093
19 B 124 ARLO 1416 308
17 C 908
33 B 126 ATH^C 130 747
28 C 322
25 B 128 BAC 1765 477
37 B 129 BMA 674 926
3 S 130 ACP 613 472
37 C 1068
16 C 1010
0 B 133 ATH^B 1289 347
18 S 134 BCO 1394 376
14 S 135 ADCT 881 38
11 B 136 AJXA 892 979
1 S 137 AGI 1725 64
18 B 138 BGX 198 530
21 S 139 BFAC 1248 137
25 S 140 ASAI 368 328
3 S 141 ARL 403 68
14 C 545
29 C 339
1 C 156
25 C 509
22 C 402
29 B 147 ABBV 1902 940
24 B 148 AFG 1314 245
33 B 149 AFT 1308 481
25 S 150 ALL^H 1494 258
36 C 1043
12 S 152 BKSY 430 705
20 S 153 ALK 1056 361
0 B 154 AZRE 1611 156
13 C 333
4 B 156 AIG^A 1838 778
13 B 157 BIT 1410 300
27 C 684
24 S 159 AAIN 1513 486
0 C 448
18 C 664
15 B 162 ADT 568 632
8 S 163 BEPI 720 24
25 C 973
15 S 165 AMH^H 1222 417
24 C 707
39 C 1006
4 B 168 BEPH 134 584
18 S 169 AGM^D 613 818
18 C 705
18 S 171 AMR 919 702
1 C 938
29 C 910
9 B 174 APE 1850 168
20 C 307
1 C 145
31 S 177 BCAT 516 71
28 B 178 ARES 1504 485
21 C 500
28 B 180 BIO/B 1536 519
2 C 746
15 C 249
25 S 183 ACR^C 1982 645
19 B 184 ARC 1252 113
27 B 185 ASB^E 1798 666
17 S 186 AAP 1681 639
16 B 187 AFTR 243 453
20 B 188 AMX 555 477
8 S 189 ASGI 576 803
6 B 190 BBUC 1842 543
26 B 191 BGY 575 674
3 C 542
37 S 193 BMA 710 903
23 C 405
30 S 195 AROC 380 492
1 C 849
6 B 197 ALSN 1033 254
37 C 359
38 B 199 ALC 572 373
6 C 344
24 C 1014
4 C 134
26 B 203 AN 1279 870
36 C 591
32 S 205 AKA 1882 130
21 C 169
29 C 1136
9 C 805
39 B 209 BHV 1958 358
10 B 210 AQNU 801 928
17 B 211 BEST 768 804
26 C 566
12 B 213 BAC^M 112 911
13 C 595
37 B 215 ARW 1569 27
10 S 216 AMRC 416 139
31 S 217 AJG 1771 391
8 B 218 AGM^D 465 707
17 S 219 BANC 1970 751
4 S 220 AMG 1047 81
2 B 221 AHL^E 1217 914
21 C 801
7 B 223 AEL^A 189 211
26 B 224 AIF 1227 993
32 S 225 ATO 1630 532
6 C 1065
17 S 227 BFLY 250 23
16 C 737
8 S 229 ATUS 281 698
30 B 230 ATHM 1349 564
18 S 231 AXS 694 920
29 C 1217
35 S 233 BDN 1055 676
5 C 538
29 B 235 ATTO 491 696
22 S 236 BBN 619 42
25 B 237 BGX 1735 446
26 S 238 BLD 1810 713
1 B 239 ASGI 360 610
22 C 720
29 B 241 AQNB 958 256
29 S 242 ALLE 1205 103
7 B 243 AUY 1426 560
26 S 244 AME 965 424
36 C 1102
6 B 246 BBU 387 930
13 C 375
0 S 248 AVB 1828 107
30 C 604
28 C 534
2 S 251 ALEX 422 206
10 S 252 AI 1965 369
4 B 253 BHVN 1848 28
26 S 254 AEG 620 444
31 S 255 BHLB 1708 591
8 S 256 BG 1647 689
22 C 1028
30 S 258 AMPX 1059 318
6 B 259 BKE 1587 212
3 S 260 AIG 1501 59
32 C 270
32 S 262 BHG 411 817
1 S 263 AN 433 651
20 B 264 ATCO 654 324
9 B 265 BIO 734 966
33 S 266 BME 366 691
27 B 267 AA 394 794
36 B 268 BHIL 1729 396
16 B 269 BFH 731 660
32 S 270 ANET 1655 558
7 S 271 BHK 848 390
14 B 272 BFK 729 391
2 B 273 AKA 1203 870
18 C 177
11 B 275 AVTR 588 102
32 S 276 ARGO^A 319 36
6 S 277 AON 1406 273
29 C 197
31 S 279 ADC 1715 167
13 B 280 ARC 384 68
35 B 281 AA 1828 39
3 C 414
15 S 283 AVNT 994 899
32 C 226
31 C 1216
21 C 418
25 C 354
0 B 288 ARCH 1749 162
2 B 289 AJX 1824 156
4 B 290 ANVS 1435 278
27 B 291 AMRC 1962 768
9 S 292 ATH^E 836 297
13 B 293 AVYA 113 401
18 B 294 AHT^D 842 816
28 C 1079
1 B 296 AMH^G 195 60
35 C 723
0 S 298 AN 527 568
20 B 299 AVNS 453 704
21 S 300 AUY 107 684
0 B 301 AFGC 738 405
18 C 940
12 S 303 ARI 764 844
8 B 304 BMA 1519 887
2 B 305 AEE 1590 668
22 C 304
24 B 307 AEFC 778 249
10 C 216
3 S 309 AEO 212 22
29 S 310 AVAL 1674 586
17 S 311 ACDI 1315 574
38 C 101
14 B 313 AKA 1541 317
9 C 935
4 B 315 BCX 123 865
3 C 705
1 C 1149
23 S 318 ADNT 1228 680
37 C 483
12 B 320 AAM^A 1745 416
14 S 321 ABR^F 1722 217
17 B 322 AMCR 733 709
3 S 323 BJ 975 813
19 B 324 BLD 815 843
13 S 325 AFG 772 641
36 S 326 ABT 518 294
6 S 327 BML^J 1631 848
33 C 826
7 S 329 BAC^Q 476 136
13 S 330 ALIT 146 631
32 S 331 BMI 213 407
20 S 332 AAIC 1998 810
17 C 1225
13 S 334 AGM^E 652 160
3 B 335 BAP 1845 311
6 B 336 BBY 1996 901
16 B 337 ADCT 1132 211
14 B 338 ALLY 1616 564
29 B 339 APAM 1476 906
39 C 300
10 S 341 APE 1885 946
15 C 1286
22 B 343 ABM 495 227
32 B 344 AXTA 670 107
4 S 345 AOD 1809 924
24 C 1155
15 S 347 ATKR 312 146
30 B 348 ARMK 1791 922
37 B 349 BKU 1357 736
31 C 1065
3 C 1281
39 S 352 ADNT 1323 532
7 C 1251
2 S 354 AFGD 1768 987
19 C 274
9 B 356 ARL 181 532
24 C 771
15 S 358 AMRX 1164 768
13 B 359 BHC 935 640
34 C 465
15 B 361 ARGD 378 837
15 S 362 AMWL 1033 815
1 B 363 BALY 1005 120
39 C 562
9 S 365 AGR 504 314
39 C 297
11 B 367 ALL^G 1320 866
16 S 368 BMI 219 452
1 C 1151
38 C 1130
12 S 371 AJRD 859 425
26 S 372 AYX 1149 658
31 B 373 BIGZ 425 911
12 B 374 AHL^D 1478 766
28 B 375 AIN 604 144
0 C 693
36 B 377 ALV 1094 26
4 B 378 ALL^H 1900 216
5 C 581
37 S 380 BAC^N 1646 834
34 B 381 BCC 1437 521
26 S 382 BFZ 1056 928
5 C 791
29 C 1169
34 S 385 AG 335 152
29 C 845
32 C 1299
37 S 388 AHL^C 1955 186
9 S 389 ATH^D 1627 335
0 B 390 AKR 839 731
3 B 391 ABR^F 148 938
29 C 183
11 B 393 ARR^C 417 462
21 B 394 AOS 1067 558
1 C 603
16 S 396 ALTG^A 478 80
21 B 397 AIN 1877 148
15 B 398 BC^A 1202 785
5 S 399 BCO 1326 218
0 B 400 BLCO 339 243
8 S 401 BBVA 1418 482
37 S 402 AEG 668 421
6 C 920
22 S 404 BG 1030 702
15 B 405 ATH^B 563 452
13 C 320
29 S 407 AMH^G 116 396
2 S 408 AL 632 832
33 B 409 AROC 1151 68
15 C 914
21 S 411 AGD 903 727
36 C 574
1 C 127
5 C 151
33 C 472
28 B 416 BGR 1411 258
19 B 417 AVD 602 355
22 C 1234
19 B 419 ARGO 981 111
23 C 671
39 B 421 AMRC 384 786
32 B 422 BHR^B 1332 695
6 C 150
38 B 424 AAT 663 539
0 C 336
33 C 778
21 S 427 ASH 229 975
21 C 314
7 C 439
20 B 430 BCSF 885 940
5 B 431 ASAI 1187 452
13 C 1088
15 C 659
36 C 1400
28 B 435 AENZ 1461 671
19 B 436 ATCO^D 214 946
2 C 959
5 B 438 A 701 402
27 S 439 ACV 700 589
24 S 440 ACRE 1288 196
17 S 441 ATEN 459 677
0 C 637
36 B 443 B 1589 511
38 B 444 BC^C 693 439
19 C 381
20 C 1018
39 B 447 AMK 1597 351
38 B 448 BEKE 1585 897
8 B 449 AKO/B 1189 977
27 C 478
2 B 451 ABR^D 1466 194
29 S 452 BAK 1242 437
27 C 1068
36 C 813
6 C 1252
39 S 456 AIG 1070 795
33 S 457 APAM 775 268
30 S 458 BGSF 179 798
34 B 459 AEL^B 865 88
31 B 460 BARK 685 873
8 B 461 ANF 234 146
24 C 897
16 S 463 AMN 954 130
12 B 464 AGL 1386 688
11 C 323
31 B 466 AJG 155 68
33 B 467 ALK 781 442
35 C 1391
16 S 469 ALCC 459 886
32 C 1306
33 C 1303
39 C 264
3 S 473 AAP 1452 785
21 S 474 BHV 599 971
18 B 475 BLUA 1133 660
23 S 476 AQN 1049 170
39 S 477 BAC^S 212 733
16 C 1435
23 B 479 ATGE 1807 17
28 S 480 ALLG 1342 41
17 C 772
16 C 1124
27 S 483 ADX 659 974
23 C 1215
19 S 485 AKA 1632 351
32 B 486 ASC 1364 541
13 C 551
1 B 488 ACDI 1426 366
25 S 489 APH 1001 753
11 C 689
6 C 477
15 S 492 BIPC 704 110
4 C 205
2 C 1241
34 S 495 AHT^H 1992 913
26 B 496 BGSX 1289 724
11 B 497 BKE 701 931
7 C 1201
17 B 499 AGM^C 1543 46
11 B 500 AVA 1622 745
15 C 353
28 B 502 AGM^F 774 73
14 B 503 BHLB 360 31
4 B 504 AFGC 632 596
7 C 515
39 C 686
36 C 308
0 C 767
18 S 509 BKDT 1627 711
9 B 510 APGB 1648 214
23 S 511 AIR 1681 319
26 S 512 BFLY 569 187
13 B 513 AMAM 302 258
7 S 514 AER 1170 1000
35 S 515 AUY 477 973
6 S 516 APG 1900 41
23 C 986
28 C 1162
19 C 1359
3 S 520 ATH^C 1998 291
30 B 521 AIR 548 82
4 C 369
4 B 523 ABG 725 720
6 B 524 BFH 335 234
34 S 525 ALLG 1235 393
6 C 616
38 B 527 AEL^B 385 917
6 C 1094
9 C 1360
11 B 530 AIT 1948 547
20 S 531 AB 1949 471
10 C 1339
18 C 584
22 S 534 AB 576 542
5 B 535 BAC^O 1101 487
39 B 536 ARGD 904 229
32 C 419
38 S 538 AWI 1152 430
36 C 301
17 C 395
12 C 1473
9 C 1475
22 S 543 AMBP 1015 270
26 B 544 BDX 334 694
11 C 470
28 B 546 ALIT 1374 260
8 S 547 AAM^B 1894 853
27 B 548 BFZ 764 617
1 S 549 AJX 525 258
39 C 1050
30 B 551 AMR 337 403
30 S 552 BKE 1219 991
32 C 747
7 C 119
11 S 555 BAM 663 295
32 S 556 BG 1549 353
14 B 557 ARC 1882 268
21 C 1250
39 B 559 BLD 377 422
37 C 1341
9 C 1515
29 B 562 BBDO 190 673
27 C 865
31 S 564 AXAC 341 723
